Workbook

Sheet README
A1: project: waste collection perfomance tracker(2025)
A2: Goal: find which zone collect the least waste per truck trip
A3: Q1:which zone collect the most and least tonnage per trip?
A4: Q2:which month peak, and by how much?
A5: Q3:which zones have the highest missed pickup rate?
A8: column | B8: meaning | C8: expected type
A9: date | B9: day of collect | C9: date
A10: zone | B10: collection zone | C10: text
A11: truck id | B11: trucks used | C11: text
A12: trips | B12: how many trips each trucks took | C12: whole number
A13: tonnage | B13: waste collected | C13: number(tons)
A14: fuel used | B14: fuel burned | C14: number (litres)
A15: missed pickups | B15: pickups not completed | C15: whole number

Sheet Issue_logs
A1: Column | B1: Problem found | C1: How many | D1: planned fix and why
A2: Whole table | B2: Rows entered twice | C2: 30 copies | D2: remove duplicate
A3: Zones | B3: Same zones spelled many ways (cases and spaces) | C3: 39 spellings for 8 zones | D3: trim spaces then capitalize each word
A4: Tonnage | B4: Text like "17.8 tons" | C4: 24 | D4: remove the tons
A5: Tonnage | B5: Blank | C5: 15 | D5: keep them but flag it
A6: Tonnage | B6: 999 typo | C6: 5 | D6: replace the 999 with blank and flag it
A7: Fuel used | B7: Blank or N/A | C7: 26 | D7: keep them
A8: Truck IDs | B8: Blank | C8: 15 | D8: replace blanks with unknown its still needed for zone totals
A9: Missed pickups | B9: Blank | C9: 15 | D9: leave blanks and exclude from the missed pick up rates assuming 0 would make zones looks better than they are
A10: Date | B10: 3 different formats | C10: 990/15/25 | D10: convert all 3 formats to real dates. The slash date are day/month/year, so use the uk nigeria english locale

Sheet raw_data
A1: Date | B1: Zone | C1: Truck ID | D1: Trips | E1: Tonnage | F1: Fuel Used (L) | G1: Missed Pickups
A2: 2025-01-22 | B2: Alimosho | C2: ALM-04 | D2: 2 | E2: 999 | F2: 72.2 | G2: 2
A3: 2025-07-09 | B3: Mushin | C3: MSH-03 | D3: 3 | E3: 21.9 | F3: 96.0 | G3: 1
A4: 2025-03-10 | B4: Badagry | C4: BDG-01 | D4: 4 | E4: 18.6 | F4: 154.0 | G4: 2
A5: 2025-05-25 | B5: Alimosho | C5: ALM-02 | D5: 2 | E5: 15.3 | F5: 72.7 | G5: 0
A6: 2025-11-02 | B6: Epe | C6: EPE-01 | D6: 2 | E6: 8.2 | F6: 83.6 | G6: 1
A7: 2025-02-04 | B7: Ikorodu | C7: IKD-02 | D7: 2 | E7: 7.6 | F7: 91.4 | G7: 1
A8: 2025-08-09 | B8: mushin | C8: MSH-02 | D8: 3 | E8: 18.4 | F8: 139.6 | G8: 2
A9: 2025-07-27 | B9: Ikeja | C9: IKJ-03 | D9: 6 | E9: 42.5 | F9: 245.3 | G9: 1
A10: 2025-06-17 | B10: Lekki | C10: LKK-02 | D10: 4 | E10: 20.5 | F10: 181.9 | G10: 2
A11: 2025-03-04 | B11: Badagry | C11: BDG-02 | D11: 2 | E11: 7.5 | F11: 65.0 | G11: 2
A12: 2025-06-07 | B12: Ikeja | C12: IKJ-02 | D12: 3 | E12: 20.1 | F12: 117.5 | G12: 1
... A15: 2025-03-09 | B15: Alimosho | C15: ALM-03 | D15: 4 | E15: 28.7 | F15: 140.3 | G15: 2
A16: 2025-02-21 | B16: Ikeja | C16: IKJ-02 | D16: 4 | F16: 186.5 | G16: 1
A17: 2025-11-30 | B17: Mushin | C17: MSH-01 | D17: 2 | E17: 17.5 | F17: 76.3 | G17: 1
A18: 2025-11-22 | B18: Surulere | C18: SRL-01 | D18: 3 | E18: 20.4 | F18: 131.0 | G18: 0
A19: 2025-07-04 | B19: Badagry | C19: BDG-02 | D19: 4 | E19: 17.2 | F19: 193.3 | G19: 1
A20: 2025-02-26 | B20: Ikorodu | C20: IKD-01 | D20: 5 | E20: 20.7 | G20: 2
A21: 2025-11-12 | B21: Ikorodu | C21: IKD-01 | D21: 5 | E21: 24.3 | F21: 172.7 | G21: 2
A22: 2025-06-02 | B22: Epe | C22: EPE-01 | D22: 2 | E22: 6.8 | F22: 80.2 | G22: 2
A23: 2025-05-24 | B23: Ikorodu | C23: IKD-03 | D23: 4 | E23: 16.9 | F23: 152.7 | G23: 3
A24: 2025-06-09 | B24: Alimosho | C24: ALM-04 | D24: 6 | E24: 39.0 | F24: 207.4 | G24: 3
A25: 2025-01-09 | B25: Alimosho | C25: ALM-01 | D25: 2 | E25: 12.3 | F25: 80.9 | G25: 0
A26: 2025-11-21 | B26: Epe | C26: EPE-01 | D26: 2 | E26: 9.0 | F26: 73.4 | G26: 0
A27: 2025-02-28 | B27: Epe | C27: EPE-01 | D27: 3 | E27: 9.2 | F27: 115.3 | G27: 2
A28: 2025-01-23 | B28: Epe | C28: EPE-02 | D28: 6 | E28: 19.2 | F28: 244.8 | G28: 2
A29: 2025-02-25 | B29: Ikeja | C29: IKJ-01 | D29: 5 | E29: 32.1 | F29: 174.3 | G29: 6
A30: 12-Oct-25 | B30: Ikorodu | C30: IKD-02 | D30: 5 | E30: 21.1 | F30: 192.0 | G30: 1
A31: 2025-10-29 | B31: ALIMOSHO | C31: ALM-03 | D31: 4 | E31: 24.5 | F31: 167.4 | G31: 1
A32: 2025-09-17 | B32: BADAGRY | C32: BDG-02 | D32: 2 | E32: 8.0 | F32: 74.9 | G32: 4
... A36: 2025-04-30 | B36: Alimosho | C36: ALM-04 | D36: 3 | E36: 22.5 | F36: 119.1 | G36: 0
A37: 2025-04-28 | B37: Ikorodu | C37: IKD-02 | D37: 5 | F37: 187.6 | G37: 1
A38: 2025-01-08 | B38: Alimosho | C38: ALM-02 | D38: 6 | E38: 50.7 | F38: 213.0 | G38: 1
A39: 2025-01-31 | B39: Mushin | C39: MSH-02 | D39: 5 | E39: 27.9 | F39: 207.5 | G39: 1
A40: 2025-02-09 | B40: Alimosho | C40: ALM-03 | D40: 5 | E40: 34.0 | F40: 234.2 | G40: 1
A41: 2025-02-24 | B41: Ikorodu | C41: IKD-03 | D41: 3 | E41: 11.0 | F41: 135.6 | G41: 3
A42: 2025-03-11 | B42: Alimosho | C42: ALM-04 | D42: 4 | E42: 29.0 | F42: 161.6 | G42: 0
A43: 2025-12-18 | B43: Badagry | C43: BDG-02 | D43: 3 | E43: 10.4 | F43: 106.8 | G43: 7
A44: 2025-05-05 | B44: Ikeja | C44: IKJ-03 | D44: 2 | E44: 13.8 | F44: 73.4
A45: 2025-06-29 | B45: Lekki | C45: LKK-01 | D45: 3 | E45: 18.6 | F45: 115.3 | G45: 1
...

Sheet zones_lookup
A1: Zone | B1: Supervisor | C1: Population
A2: Ikeja | B2: Mr. Adeyemi | C2: 313000
A3: Surulere | B3: Mrs. Okafor | C3: 503000
A4: Alimosho | B4: Mr. Bello | C4: 1288000
A5: Ikorodu | B5: Mrs. Eze | C5: 535000
A6: Lekki | B6: Mr. Salami | C6: 200000
A7: Mushin | B7: Mrs. Adisa | C7: 633000
A8: Epe | B8: Mr. Ogunleye | C8: 181000
A9: Badagry | B9: Mrs. Johnson | C9: 241000

Sheet Clean_data
A1: Date | B1: Zone | C1: Truck ID | D1: Trips | E1: Tonnage | F1: Fuel Used (L) | G1: Missed Pickups | H1: Month | I1: Month Name | J1: Tonage per Trip | K1: Supervisor | L1: Population
A2: 45679 | B2: Alimosho | C2: ALM-04 | D2: 2 | F2: 72.2 | G2: 2 | H2: 1 | I2: January | K2: =_xlfn.XLOOKUP(B2,zones_lookup!A:A,zones_lookup!B:B,"Not found") -> Mr. Bello | L2: =_xlfn.XLOOKUP(B2,zones_lookup!A:A,zones_lookup!C:C,"Not found") -> 1288000
A3: 45847 | B3: Mushin | C3: MSH-03 | D3: 3 | E3: 21.9 | F3: 96 | G3: 1 | H3: 7 | I3: July | J3: 7.3 | K3: =_xlfn.XLOOKUP(B3,zones_lookup!A:A,zones_lookup!B:B,"Not found") -> Mrs. Adisa | L3: =_xlfn.XLOOKUP(B3,zones_lookup!A:A,zones_lookup!C:C,"Not found") -> 633000
A4: 45726 | B4: Badagry | C4: BDG-01 | D4: 4 | E4: 18.6 | F4: 154 | G4: 2 | H4: 3 | I4: March | J4: 4.65 | K4: =_xlfn.XLOOKUP(B4,zones_lookup!A:A,zones_lookup!B:B,"Not found") -> Mrs. Johnson | L4: =_xlfn.XLOOKUP(B4,zones_lookup!A:A,zones_lookup!C:C,"Not found") -> 241000
A5: 45802 | B5: Alimosho | C5: ALM-02 | D5: 2 | E5: 15.3 | F5: 72.7 | G5: 0 | H5: 5 | I5: May | J5: 7.65 | K5: =_xlfn.XLOOKUP(B5,zones_lookup!A:A,zones_lookup!B:B,"Not found") -> Mr. Bello | L5: =_xlfn.XLOOKUP(B5,zones_lookup!A:A,zones_lookup!C:C,"Not found") -> 1288000
A6: 45963 | B6: Epe | C6: EPE-01 | D6: 2 | E6: 8.2 | F6: 83.6 | G6: 1 | H6: 11 | I6: November | J6: 4.1 | K6: =_xlfn.XLOOKUP(B6,zones_lookup!A:A,zones_lookup!B:B,"Not found") -> Mr. Ogunleye | L6: =_xlfn.XLOOKUP(B6,zones_lookup!A:A,zones_lookup!C:C,"Not found") -> 181000
A7: 45692 | B7: Ikorodu | C7: IKD-02 | D7: 2 | E7: 7.6 | F7: 91.4 | G7: 1 | H7: 2 | I7: February | J7: 3.8 | K7: =_xlfn.XLOOKUP(B7,zones_lookup!A:A,zones_lookup!B:B,"Not found") -> Mrs. Eze | L7: =_xlfn.XLOOKUP(B7,zones_lookup!A:A,zones_lookup!C:C,"Not found") -> 535000
A8: 45878 | B8: Mushin | C8: MSH-02 | D8: 3 | E8: 18.4 | F8: 139.6 | G8: 2 | H8: 8 | I8: August | J8: 6.1333333 | K8: =_xlfn.XLOOKUP(B8,zones_lookup!A:A,zones_lookup!B:B,"Not found") -> Mrs. Adisa | L8: =_xlfn.XLOOKUP(B8,zones_lookup!A:A,zones_lookup!C:C,"Not found") -> 633000
A9: 45865 | B9: Ikeja | C9: IKJ-03 | D9: 6 | E9: 42.5 | F9: 245.3 | G9: 1 | H9: 7 | I9: July | J9: 7.0833333 | K9: =_xlfn.XLOOKUP(B9,zones_lookup!A:A,zones_lookup!B:B,"Not found") -> Mr. Adeyemi | L9: =_xlfn.XLOOKUP(B9,zones_lookup!A:A,zones_lookup!C:C,"Not found") -> 313000
A10: 45825 | B10: Lekki | C10: LKK-02 | D10: 4 | E10: 20.5 | F10: 181.9 | G10: 2 | H10: 6 | I10: June | J10: 5.125 | K10: =_xlfn.XLOOKUP(B10,zones_lookup!A:A,zones_lookup!B:B,"Not found") -> Mr. Salami | L10: =_xlfn.XLOOKUP(B10,zones_lookup!A:A,zones_lookup!C:C,"Not found") -> 200000
A11: 45720 | B11: Badagry | C11: BDG-02 | D11: 2 | E11: 7.5 | F11: 65 | G11: 2 | H11: 3 | I11: March | J11: 3.75 | K11: =_xlfn.XLOOKUP(B11,zones_lookup!A:A,zones_lookup!B:B,"Not found") -> Mrs. Johnson | L11: =_xlfn.XLOOKUP(B11,zones_lookup!A:A,zones_lookup!C:C,"Not found") -> 241000
A12: 45815 | B12: Ikeja | C12: IKJ-02 | D12: 3 | E12: 20.1 | F12: 117.5 | G12: 1 | H12: 6 | I12: June | J12: 6.7 | K12: =_xlfn.XLOOKUP(B12,zones_lookup!A:A,zones_lookup!B:B,"Not found") -> Mr. Adeyemi | L12: =_xlfn.XLOOKUP(B12,zones_lookup!A:A,zones_lookup!C:C,"Not found") -> 313000
A13: 45758 | B13: Epe | C13: EPE-01 | D13: 6 | E13: 22.9 | F13: 255.3 | G13: 2 | H13: 4 | I13: April | J13: 3.8166667 | K13: =_xlfn.XLOOKUP(B13,zones_lookup!A:A,zones_lookup!B:B,"Not found") -> Mr. Ogunleye | L13: =_xlfn.XLOOKUP(B13,zones_lookup!A:A,zones_lookup!C:C,"Not found") -> 181000
A14: 45810 | B14: Mushin | C14: MSH-03 | D14: 5 | E14: 33.9 | F14: 169.5 | G14: 1 | H14: 6 | I14: June | J14: 6.78 | K14: =_xlfn.XLOOKUP(B14,zones_lookup!A:A,zones_lookup!B:B,"Not found") -> Mrs. Adisa | L14: =_xlfn.XLOOKUP(B14,zones_lookup!A:A,zones_lookup!C:C,"Not found") -> 633000
A15: 45725 | B15: Alimosho | C15: ALM-03 | D15: 4 | E15: 28.7 | F15: 140.3 | G15: 2 | H15: 3 | I15: March | J15: 7.175 | K15: =_xlfn.XLOOKUP(B15,zones_lookup!A:A,zones_lookup!B:B,"Not found") -> Mr. Bello | L15: =_xlfn.XLOOKUP(B15,zones_lookup!A:A,zones_lookup!C:C,"Not found") -> 1288000
A16: 45709 | B16: Ikeja | C16: IKJ-02 | D16: 4 | F16: 186.5 | G16: 1 | H16: 2 | I16: February | K16: =_xlfn.XLOOKUP(B16,zones_lookup!A:A,zones_lookup!B:B,"Not found") -> Mr. Adeyemi | L16: =_xlfn.XLOOKUP(B16,zones_lookup!A:A,zones_lookup!C:C,"Not found") -> 313000
A17: 45991 | B17: Mushin | C17: MSH-01 | D17: 2 | E17: 17.5 | F17: 76.3 | G17: 1 | H17: 11 | I17: November | J17: 8.75 | K17: =_xlfn.XLOOKUP(B17,zones_lookup!A:A,zones_lookup!B:B,"Not found") -> Mrs. Adisa | L17: =_xlfn.XLOOKUP(B17,zones_lookup!A:A,zones_lookup!C:C,"Not found") -> 633000
A18: 45983 | B18: Surulere | C18: SRL-01 | D18: 3 | E18: 20.4 | F18: 131 | G18: 0 | H18: 11 | I18: November | J18: 6.8 | K18: =_xlfn.XLOOKUP(B18,zones_lookup!A:A,zones_lookup!B:B,"Not found") -> Mrs. Okafor | L18: =_xlfn.XLOOKUP(B18,zones_lookup!A:A,zones_lookup!C:C,"Not found") -> 503000
A19: 45842 | B19: Badagry | C19: BDG-02 | D19: 4 | E19: 17.2 | F19: 193.3 | G19: 1 | H19: 7 | I19: July | J19: 4.3 | K19: =_xlfn.XLOOKUP(B19,zones_lookup!A:A,zones_lookup!B:B,"Not found") -> Mrs. Johnson | L19: =_xlfn.XLOOKUP(B19,zones_lookup!A:A,zones_lookup!C:C,"Not found") -> 241000
A20: 45714 | B20: Ikorodu | C20: IKD-01 | D20: 5 | E20: 20.7 | G20: 2 | H20: 2 | I20: February | J20: 4.14 | K20: =_xlfn.XLOOKUP(B20,zones_lookup!A:A,zones_lookup!B:B,"Not found") -> Mrs. Eze | L20: =_xlfn.XLOOKUP(B20,zones_lookup!A:A,zones_lookup!C:C,"Not found") -> 535000
A21: 45973 | B21: Ikorodu | C21: IKD-01 | D21: 5 | E21: 24.3 | F21: 172.7 | G21: 2 | H21: 11 | I21: November | J21: 4.86 | K21: =_xlfn.XLOOKUP(B21,zones_lookup!A:A,zones_lookup!B:B,"Not found") -> Mrs. Eze | L21: =_xlfn.XLOOKUP(B21,zones_lookup!A:A,zones_lookup!C:C,"Not found") -> 535000
A22: 45810 | B22: Epe | C22: EPE-01 | D22: 2 | E22: 6.8 | F22: 80.2 | G22: 2 | H22: 6 | I22: June | J22: 3.4 | K22: =_xlfn.XLOOKUP(B22,zones_lookup!A:A,zones_lookup!B:B,"Not found") -> Mr. Ogunleye | L22: =_xlfn.XLOOKUP(B22,zones_lookup!A:A,zones_lookup!C:C,"Not found") -> 181000
A23: 45801 | B23: Ikorodu | C23: IKD-03 | D23: 4 | E23: 16.9 | F23: 152.7 | G23: 3 | H23: 5 | I23: May | J23: 4.225 | K23: =_xlfn.XLOOKUP(B23,zones_lookup!A:A,zones_lookup!B:B,"Not found") -> Mrs. Eze | L23: =_xlfn.XLOOKUP(B23,zones_lookup!A:A,zones_lookup!C:C,"Not found") -> 535000
A24: 45817 | B24: Alimosho | C24: ALM-04 | D24: 6 | E24: 39 | F24: 207.4 | G24: 3 | H24: 6 | I24: June | J24: 6.5 | K24: =_xlfn.XLOOKUP(B24,zones_lookup!A:A,zones_lookup!B:B,"Not found") -> Mr. Bello | L24: =_xlfn.XLOOKUP(B24,zones_lookup!A:A,zones_lookup!C:C,"Not found") -> 1288000
A25: 45666 | B25: Alimosho | C25: ALM-01 | D25: 2 | E25: 12.3 | F25: 80.9 | G25: 0 | H25: 1 | I25: January | J25: 6.15 | K25: =_xlfn.XLOOKUP(B25,zones_lookup!A:A,zones_lookup!B:B,"Not found") -> Mr. Bello | L25: =_xlfn.XLOOKUP(B25,zones_lookup!A:A,zones_lookup!C:C,"Not found") -> 1288000
A26: 45982 | B26: Epe | C26: EPE-01 | D26: 2 | E26: 9 | F26: 73.4 | G26: 0 | H26: 11 | I26: November | J26: 4.5 | K26: =_xlfn.XLOOKUP(B26,zones_lookup!A:A,zones_lookup!B:B,"Not found") -> Mr. Ogunleye | L26: =_xlfn.XLOOKUP(B26,zones_lookup!A:A,zones_lookup!C:C,"Not found") -> 181000
A27: 45716 | B27: Epe | C27: EPE-01 | D27: 3 | E27: 9.2 | F27: 115.3 | G27: 2 | H27: 2 | I27: February | J27: 3.0666667 | K27: =_xlfn.XLOOKUP(B27,zones_lookup!A:A,zones_lookup!B:B,"Not found") -> Mr. Ogunleye | L27: =_xlfn.XLOOKUP(B27,zones_lookup!A:A,zones_lookup!C:C,"Not found") -> 181000
A28: 45680 | B28: Epe | C28: EPE-02 | D28: 6 | E28: 19.2 | F28: 244.8 | G28: 2 | H28: 1 | I28: January | J28: 3.2 | K28: =_xlfn.XLOOKUP(B28,zones_lookup!A:A,zones_lookup!B:B,"Not found") -> Mr. Ogunleye | L28: =_xlfn.XLOOKUP(B28,zones_lookup!A:A,zones_lookup!C:C,"Not found") -> 181000
A29: 45713 | B29: Ikeja | C29: IKJ-01 | D29: 5 | E29: 32.1 | F29: 174.3 | G29: 6 | H29: 2 | I29: February | J29: 6.42 | K29: =_xlfn.XLOOKUP(B29,zones_lookup!A:A,zones_lookup!B:B,"Not found") -> Mr. Adeyemi | L29: =_xlfn.XLOOKUP(B29,zones_lookup!A:A,zones_lookup!C:C,"Not found") -> 313000
A30: 45942 | B30: Ikorodu | C30: IKD-02 | D30: 5 | E30: 21.1 | F30: 192 | G30: 1 | H30: 10 | I30: October | J30: 4.22 | K30: =_xlfn.XLOOKUP(B30,zones_lookup!A:A,zones_lookup!B:B,"Not found") -> Mrs. Eze | L30: =_xlfn.XLOOKUP(B30,zones_lookup!A:A,zones_lookup!C:C,"Not found") -> 535000
A31: 45959 | B31: Alimosho | C31: ALM-03 | D31: 4 | E31: 24.5 | F31: 167.4 | G31: 1 | H31: 10 | I31: October | J31: 6.125 | K31: =_xlfn.XLOOKUP(B31,zones_lookup!A:A,zones_lookup!B:B,"Not found") -> Mr. Bello | L31: =_xlfn.XLOOKUP(B31,zones_lookup!A:A,zones_lookup!C:C,"Not found") -> 1288000
A32: 45917 | B32: Badagry | C32: BDG-02 | D32: 2 | E32: 8 | F32: 74.9 | G32: 4 | H32: 9 | I32: September | J32: 4 | K32: =_xlfn.XLOOKUP(B32,zones_lookup!A:A,zones_lookup!B:B,"Not found") -> Mrs. Johnson | L32: =_xlfn.XLOOKUP(B32,zones_lookup!A:A,zones_lookup!C:C,"Not found") -> 241000
A33: 45720 | B33: Epe | C33: EPE-02 | D33: 5 | E33: 19.9 | G33: 2 | H33: 3 | I33: March | J33: 3.98 | K33: =_xlfn.XLOOKUP(B33,zones_lookup!A:A,zones_lookup!B:B,"Not found") -> Mr. Ogunleye | L33: =_xlfn.XLOOKUP(B33,zones_lookup!A:A,zones_lookup!C:C,"Not found") -> 181000
A34: 45925 | B34: Epe | C34: EPE-01 | D34: 2 | E34: 7.9 | F34: 90.2 | G34: 1 | H34: 9 | I34: September | J34: 3.95 | K34: =_xlfn.XLOOKUP(B34,zones_lookup!A:A,zones_lookup!B:B,"Not found") -> Mr. Ogunleye | L34: =_xlfn.XLOOKUP(B34,zones_lookup!A:A,zones_lookup!C:C,"Not found") -> 181000
A35: 45731 | B35: Ikeja | C35: IKJ-03 | D35: 4 | E35: 25.4 | F35: 175.4 | G35: 0 | H35: 3 | I35: March | J35: 6.35 | K35: =_xlfn.XLOOKUP(B35,zones_lookup!A:A,zones_lookup!B:B,"Not found") -> Mr. Adeyemi | L35: =_xlfn.XLOOKUP(B35,zones_lookup!A:A,zones_lookup!C:C,"Not found") -> 313000
A36: 45777 | B36: Alimosho | C36: ALM-04 | D36: 3 | E36: 22.5 | F36: 119.1 | G36: 0 | H36: 4 | I36: April | J36: 7.5 | K36: =_xlfn.XLOOKUP(B36,zones_lookup!A:A,zones_lookup!B:B,"Not found") -> Mr. Bello | L36: =_xlfn.XLOOKUP(B36,zones_lookup!A:A,zones_lookup!C:C,"Not found") -> 1288000
A37: 45775 | B37: Ikorodu | C37: IKD-02 | D37: 5 | F37: 187.6 | G37: 1 | H37: 4 | I37: April | K37: =_xlfn.XLOOKUP(B37,zones_lookup!A:A,zones_lookup!B:B,"Not found") -> Mrs. Eze | L37: =_xlfn.XLOOKUP(B37,zones_lookup!A:A,zones_lookup!C:C,"Not found") -> 535000
A38: 45665 | B38: Alimosho | C38: ALM-02 | D38: 6 | E38: 50.7 | F38: 213 | G38: 1 | H38: 1 | I38: January | J38: 8.45 | K38: =_xlfn.XLOOKUP(B38,zones_lookup!A:A,zones_lookup!B:B,"Not found") -> Mr. Bello | L38: =_xlfn.XLOOKUP(B38,zones_lookup!A:A,zones_lookup!C:C,"Not found") -> 1288000
A39: 45688 | B39: Mushin | C39: MSH-02 | D39: 5 | E39: 27.9 | F39: 207.5 | G39: 1 | H39: 1 | I39: January | J39: 5.58 | K39: =_xlfn.XLOOKUP(B39,zones_lookup!A:A,zones_lookup!B:B,"Not found") -> Mrs. Adisa | L39: =_xlfn.XLOOKUP(B39,zones_lookup!A:A,zones_lookup!C:C,"Not found") -> 633000
A40: 45697 | B40: Alimosho | C40: ALM-03 | D40: 5 | E40: 34 | F40: 234.2 | G40: 1 | H40: 2 | I40: February | J40: 6.8 | K40: =_xlfn.XLOOKUP(B40,zones_lookup!A:A,zones_lookup!B:B,"Not found") -> Mr. Bello | L40: =_xlfn.XLOOKUP(B40,zones_lookup!A:A,zones_lookup!C:C,"Not found") -> 1288000
...

Sheet pivot table
A3: Row Labels | B3: Average of Tonage per Trip
A4: Alimosho | B4: 7.20901
A5: Mushin | B5: 7.1319417 | F5: Row Labels | G5: Average of Missed Pickups
A6: Ikeja | B6: 6.8626782 | F6: Ikorodu | G6: 2.5639098
A7: Surulere | B7: 6.3296581 | F7: Badagry | G7: 2.5084746
A8: Lekki | B8: 5.593033 | F8: Epe | G8: 2.4112903
A9: Ikorodu | B9: 4.1955556 | F9: Mushin | G9: 1.3592233
A10: Badagry | B10: 3.9405932 | F10: Lekki | G10: 1.3035714
A11: Epe | B11: 3.7123278 | F11: Alimosho | G11: 1.1716418
A12: Grand Total | B12: 5.6304779 | F12: Ikeja | G12: 1.1258741
F13: Surulere | G13: 1.1016949
F14: Grand Total | G14: 1.6954315
A19: Row Labels | B19: Sum of Tonnage
A20: December | B20: 2346.8
A21: June | B21: 2078
A22: March | B22: 2017.8
A23: January | B23: 1978.8
A24: July | B24: 1819.4
A25: October | B25: 1804.7
A26: September | B26: 1794.2
A27: November | B27: 1760.8
A28: May | B28: 1718
A29: April | B29: 1693
A30: February | B30: 1472.6
A31: August | B31: 1444.1
A32: Grand Total | B32: 21928.2

Sheet Summary
B1: Waste Collection Analysis Summary
J6: Q1:which zone collect the most and least tonnage per trip?
J7: Alimosho collects the most per trip
J8: (about 7.2 tons) and Epe has the least(about 3.7),
J9: so a trip in Alimosho collects nearly twice as much.
J19: Q2:which month peak, and by how much?
J20: December is the peak month at about 2,347 tons
J21: around 62% above August
J22: the lowest month about 1,444 tons
J37: Q3:which zones have the highest missed pickup rate?
J38: Ikorodu (2.56), Badagry(2.51) and Epe(2.41)
J39: have the highest missed pickup rate
J40: while surulere has the lowest (1.10)
B56: Key Takeaway
B57: Epe, Badagry and Ikorodu are weak on both
B58: Tonnage per trip and missed pickups
B59: so they are the zones to prioritise.
B63: Data Notes
B64: 30 duplicate rows were removed.
B65: Zone name were trimmed and standardised to title case.
B66: In Tonnage, the tons "text" were removed and the 999 placeholder
B67: values were treated as missing
B68: Fuel used was converted to decimal numbers
B69: Trips and missed pickups to whole numbers
B70: Dates changed to English (UK) format
... B73: the related averages and totals, so monthly totals may be slightly understated
